16-10-27 08:12:44 homeassistant.components.recorder: Ended unfinished session (id=47 from 2016-10-26 07:44:12.673436)
16-10-27 08:12:44 homeassistant.components.recorder: Found unfinished sessions
16-10-27 09:07:41 netdisco.ssdp: Error fetching description at http://192.168.1.108:8008/ssdp/device-desc.xml
16-10-27 09:07:44 netdisco.ssdp: Error fetching description at http://192.168.1.108:37561/sony/webapi/ssdp/dd.xml
16-10-27 09:07:47 netdisco.ssdp: Error fetching description at http://192.168.1.108:1432/dd.xml
16-10-27 09:30:12 pychromecast.socket_client: Heartbeat timeout, resetting connection
16-10-27 09:30:42 pychromecast.socket_client: Failed to connect, retrying in 5.000000s
Traceback (most recent call last):
  File "/usr/local/lib/python3.5/site-packages/pychromecast/socket_client.py", line 233, in initialize_connection
    self.socket.connect((self.host, self.port))
  File "/usr/local/lib/python3.5/ssl.py", line 1019, in connect
    self._real_connect(addr, False)
  File "/usr/local/lib/python3.5/ssl.py", line 1006, in _real_connect
    socket.connect(self, addr)
socket.timeout: timed out
16-10-27 09:32:05 pychromecast.socket_client: Heartbeat timeout, resetting connection
16-10-27 09:32:35 pychromecast.socket_client: Failed to connect, retrying in 5.000000s
Traceback (most recent call last):
  File "/usr/local/lib/python3.5/site-packages/pychromecast/socket_client.py", line 233, in initialize_connection
    self.socket.connect((self.host, self.port))
  File "/usr/local/lib/python3.5/ssl.py", line 1019, in connect
    self._real_connect(addr, False)
  File "/usr/local/lib/python3.5/ssl.py", line 1006, in _real_connect
    socket.connect(self, addr)
socket.timeout: timed out
16-10-27 09:34:20 pychromecast.socket_client: Heartbeat timeout, resetting connection
16-10-27 09:34:50 pychromecast.socket_client: Failed to connect, retrying in 5.000000s
Traceback (most recent call last):
  File "/usr/local/lib/python3.5/site-packages/pychromecast/socket_client.py", line 233, in initialize_connection
    self.socket.connect((self.host, self.port))
  File "/usr/local/lib/python3.5/ssl.py", line 1019, in connect
    self._real_connect(addr, False)
  File "/usr/local/lib/python3.5/ssl.py", line 1006, in _real_connect
    socket.connect(self, addr)
socket.timeout: timed out
16-10-27 09:37:35 pychromecast.socket_client: Heartbeat timeout, resetting connection
16-10-27 09:38:05 pychromecast.socket_client: Failed to connect, retrying in 5.000000s
Traceback (most recent call last):
  File "/usr/local/lib/python3.5/site-packages/pychromecast/socket_client.py", line 233, in initialize_connection
    self.socket.connect((self.host, self.port))
  File "/usr/local/lib/python3.5/ssl.py", line 1019, in connect
    self._real_connect(addr, False)
  File "/usr/local/lib/python3.5/ssl.py", line 1006, in _real_connect
    socket.connect(self, addr)
socket.timeout: timed out
16-10-27 09:45:20 pychromecast.socket_client: Heartbeat timeout, resetting connection
16-10-27 09:51:26 pychromecast.socket_client: Heartbeat timeout, resetting connection
16-10-27 09:51:56 pychromecast.socket_client: Failed to connect, retrying in 5.000000s
Traceback (most recent call last):
  File "/usr/local/lib/python3.5/site-packages/pychromecast/socket_client.py", line 233, in initialize_connection
    self.socket.connect((self.host, self.port))
  File "/usr/local/lib/python3.5/ssl.py", line 1019, in connect
    self._real_connect(addr, False)
  File "/usr/local/lib/python3.5/ssl.py", line 1006, in _real_connect
    socket.connect(self, addr)
socket.timeout: timed out
16-10-27 09:53:34 pychromecast.socket_client: Heartbeat timeout, resetting connection
16-10-27 09:58:20 pychromecast.socket_client: Heartbeat timeout, resetting connection
16-10-27 09:59:15 pychromecast.socket_client: Heartbeat timeout, resetting connection
16-10-27 09:59:45 pychromecast.socket_client: Failed to connect, retrying in 5.000000s
Traceback (most recent call last):
  File "/usr/local/lib/python3.5/site-packages/pychromecast/socket_client.py", line 233, in initialize_connection
    self.socket.connect((self.host, self.port))
  File "/usr/local/lib/python3.5/ssl.py", line 1019, in connect
    self._real_connect(addr, False)
  File "/usr/local/lib/python3.5/ssl.py", line 1006, in _real_connect
    socket.connect(self, addr)
socket.timeout: timed out
16-10-27 10:43:58 pychromecast.socket_client: Heartbeat timeout, resetting connection
16-10-27 10:43:58 pychromecast.socket_client: Failed to connect, retrying in 5.000000s
Traceback (most recent call last):
  File "/usr/local/lib/python3.5/site-packages/pychromecast/socket_client.py", line 233, in initialize_connection
    self.socket.connect((self.host, self.port))
  File "/usr/local/lib/python3.5/ssl.py", line 1019, in connect
    self._real_connect(addr, False)
  File "/usr/local/lib/python3.5/ssl.py", line 1006, in _real_connect
    socket.connect(self, addr)
OSError: [Errno 101] Network is unreachable
16-10-27 10:57:25 pychromecast.socket_client: Heartbeat timeout, resetting connection
16-10-27 11:43:02 pychromecast.socket_client: Heartbeat timeout, resetting connection
16-10-27 12:38:47 pychromecast.socket_client: Failed to connect, retrying in 5.000000s
Traceback (most recent call last):
  File "/usr/local/lib/python3.5/site-packages/pychromecast/socket_client.py", line 233, in initialize_connection
    self.socket.connect((self.host, self.port))
  File "/usr/local/lib/python3.5/ssl.py", line 1019, in connect
    self._real_connect(addr, False)
  File "/usr/local/lib/python3.5/ssl.py", line 1006, in _real_connect
    socket.connect(self, addr)
socket.timeout: timed out
16-10-27 15:14:26 pychromecast.socket_client: Heartbeat timeout, resetting connection
16-10-27 15:14:56 pychromecast.socket_client: Failed to connect, retrying in 5.000000s
Traceback (most recent call last):
  File "/usr/local/lib/python3.5/site-packages/pychromecast/socket_client.py", line 233, in initialize_connection
    self.socket.connect((self.host, self.port))
  File "/usr/local/lib/python3.5/ssl.py", line 1019, in connect
    self._real_connect(addr, False)
  File "/usr/local/lib/python3.5/ssl.py", line 1006, in _real_connect
    socket.connect(self, addr)
socket.timeout: timed out
16-10-27 15:26:12 pychromecast.socket_client: Heartbeat timeout, resetting connection
16-10-27 15:26:42 pychromecast.socket_client: Failed to connect, retrying in 5.000000s
Traceback (most recent call last):
  File "/usr/local/lib/python3.5/site-packages/pychromecast/socket_client.py", line 233, in initialize_connection
    self.socket.connect((self.host, self.port))
  File "/usr/local/lib/python3.5/ssl.py", line 1019, in connect
    self._real_connect(addr, False)
  File "/usr/local/lib/python3.5/ssl.py", line 1006, in _real_connect
    socket.connect(self, addr)
socket.timeout: timed out
16-10-27 15:31:53 pychromecast.socket_client: Heartbeat timeout, resetting connection
16-10-27 15:32:23 pychromecast.socket_client: Failed to connect, retrying in 5.000000s
Traceback (most recent call last):
  File "/usr/local/lib/python3.5/site-packages/pychromecast/socket_client.py", line 233, in initialize_connection
    self.socket.connect((self.host, self.port))
  File "/usr/local/lib/python3.5/ssl.py", line 1019, in connect
    self._real_connect(addr, False)
  File "/usr/local/lib/python3.5/ssl.py", line 1006, in _real_connect
    socket.connect(self, addr)
socket.timeout: timed out
16-10-27 15:41:16 pychromecast.socket_client: Heartbeat timeout, resetting connection
16-10-27 15:41:46 pychromecast.socket_client: Failed to connect, retrying in 5.000000s
Traceback (most recent call last):
  File "/usr/local/lib/python3.5/site-packages/pychromecast/socket_client.py", line 233, in initialize_connection
    self.socket.connect((self.host, self.port))
  File "/usr/local/lib/python3.5/ssl.py", line 1019, in connect
    self._real_connect(addr, False)
  File "/usr/local/lib/python3.5/ssl.py", line 1006, in _real_connect
    socket.connect(self, addr)
socket.timeout: timed out
16-10-27 15:44:21 pychromecast.socket_client: Heartbeat timeout, resetting connection
16-10-27 15:44:51 pychromecast.socket_client: Failed to connect, retrying in 5.000000s
Traceback (most recent call last):
  File "/usr/local/lib/python3.5/site-packages/pychromecast/socket_client.py", line 233, in initialize_connection
    self.socket.connect((self.host, self.port))
  File "/usr/local/lib/python3.5/ssl.py", line 1019, in connect
    self._real_connect(addr, False)
  File "/usr/local/lib/python3.5/ssl.py", line 1006, in _real_connect
    socket.connect(self, addr)
socket.timeout: timed out
16-10-27 15:46:01 pychromecast.socket_client: Heartbeat timeout, resetting connection
16-10-27 15:46:31 pychromecast.socket_client: Failed to connect, retrying in 5.000000s
Traceback (most recent call last):
  File "/usr/local/lib/python3.5/site-packages/pychromecast/socket_client.py", line 233, in initialize_connection
    self.socket.connect((self.host, self.port))
  File "/usr/local/lib/python3.5/ssl.py", line 1019, in connect
    self._real_connect(addr, False)
  File "/usr/local/lib/python3.5/ssl.py", line 1006, in _real_connect
    socket.connect(self, addr)
socket.timeout: timed out
16-10-27 15:46:57 pychromecast.socket_client: Heartbeat timeout, resetting connection
16-10-27 15:47:27 pychromecast.socket_client: Failed to connect, retrying in 5.000000s
Traceback (most recent call last):
  File "/usr/local/lib/python3.5/site-packages/pychromecast/socket_client.py", line 233, in initialize_connection
    self.socket.connect((self.host, self.port))
  File "/usr/local/lib/python3.5/ssl.py", line 1019, in connect
    self._real_connect(addr, False)
  File "/usr/local/lib/python3.5/ssl.py", line 1006, in _real_connect
    socket.connect(self, addr)
socket.timeout: timed out
16-10-27 15:48:12 pychromecast.socket_client: Heartbeat timeout, resetting connection
16-10-27 15:48:42 pychromecast.socket_client: Failed to connect, retrying in 5.000000s
Traceback (most recent call last):
  File "/usr/local/lib/python3.5/site-packages/pychromecast/socket_client.py", line 233, in initialize_connection
    self.socket.connect((self.host, self.port))
  File "/usr/local/lib/python3.5/ssl.py", line 1019, in connect
    self._real_connect(addr, False)
  File "/usr/local/lib/python3.5/ssl.py", line 1006, in _real_connect
    socket.connect(self, addr)
socket.timeout: timed out
16-10-27 15:50:18 pychromecast.socket_client: Heartbeat timeout, resetting connection
16-10-27 15:50:48 pychromecast.socket_client: Failed to connect, retrying in 5.000000s
Traceback (most recent call last):
  File "/usr/local/lib/python3.5/site-packages/pychromecast/socket_client.py", line 233, in initialize_connection
    self.socket.connect((self.host, self.port))
  File "/usr/local/lib/python3.5/ssl.py", line 1019, in connect
    self._real_connect(addr, False)
  File "/usr/local/lib/python3.5/ssl.py", line 1006, in _real_connect
    socket.connect(self, addr)
socket.timeout: timed out
16-10-27 15:52:18 pychromecast.socket_client: Heartbeat timeout, resetting connection
16-10-27 15:52:48 pychromecast.socket_client: Failed to connect, retrying in 5.000000s
Traceback (most recent call last):
  File "/usr/local/lib/python3.5/site-packages/pychromecast/socket_client.py", line 233, in initialize_connection
    self.socket.connect((self.host, self.port))
  File "/usr/local/lib/python3.5/ssl.py", line 1019, in connect
    self._real_connect(addr, False)
  File "/usr/local/lib/python3.5/ssl.py", line 1006, in _real_connect
    socket.connect(self, addr)
socket.timeout: timed out
16-10-27 15:54:19 pychromecast.socket_client: Heartbeat timeout, resetting connection
16-10-27 15:54:49 pychromecast.socket_client: Failed to connect, retrying in 5.000000s
Traceback (most recent call last):
  File "/usr/local/lib/python3.5/site-packages/pychromecast/socket_client.py", line 233, in initialize_connection
    self.socket.connect((self.host, self.port))
  File "/usr/local/lib/python3.5/ssl.py", line 1019, in connect
    self._real_connect(addr, False)
  File "/usr/local/lib/python3.5/ssl.py", line 1006, in _real_connect
    socket.connect(self, addr)
socket.timeout: timed out
16-10-27 15:55:24 pychromecast.socket_client: Heartbeat timeout, resetting connection
16-10-27 15:55:54 pychromecast.socket_client: Failed to connect, retrying in 5.000000s
Traceback (most recent call last):
  File "/usr/local/lib/python3.5/site-packages/pychromecast/socket_client.py", line 233, in initialize_connection
    self.socket.connect((self.host, self.port))
  File "/usr/local/lib/python3.5/ssl.py", line 1019, in connect
    self._real_connect(addr, False)
  File "/usr/local/lib/python3.5/ssl.py", line 1006, in _real_connect
    socket.connect(self, addr)
socket.timeout: timed out
16-10-27 16:13:25 pychromecast.socket_client: Heartbeat timeout, resetting connection
16-10-27 16:13:25 pychromecast.socket_client: Failed to connect, retrying in 5.000000s
Traceback (most recent call last):
  File "/usr/local/lib/python3.5/site-packages/pychromecast/socket_client.py", line 233, in initialize_connection
    self.socket.connect((self.host, self.port))
  File "/usr/local/lib/python3.5/ssl.py", line 1019, in connect
    self._real_connect(addr, False)
  File "/usr/local/lib/python3.5/ssl.py", line 1006, in _real_connect
    socket.connect(self, addr)
OSError: [Errno 101] Network is unreachable
16-10-27 16:14:03 pychromecast.socket_client: Heartbeat timeout, resetting connection
16-10-27 16:17:27 pychromecast.socket_client: Heartbeat timeout, resetting connection
16-10-27 16:19:17 pychromecast.socket_client: Heartbeat timeout, resetting connection
16-10-27 16:25:56 pychromecast.socket_client: Heartbeat timeout, resetting connection
16-10-27 16:26:26 pychromecast.socket_client: Failed to connect, retrying in 5.000000s
Traceback (most recent call last):
  File "/usr/local/lib/python3.5/site-packages/pychromecast/socket_client.py", line 233, in initialize_connection
    self.socket.connect((self.host, self.port))
  File "/usr/local/lib/python3.5/ssl.py", line 1019, in connect
    self._real_connect(addr, False)
  File "/usr/local/lib/python3.5/ssl.py", line 1006, in _real_connect
    socket.connect(self, addr)
socket.timeout: timed out
16-10-27 16:30:08 pychromecast.socket_client: Heartbeat timeout, resetting connection
16-10-27 16:31:30 pychromecast.socket_client: Heartbeat timeout, resetting connection
16-10-27 16:32:00 pychromecast.socket_client: Failed to connect, retrying in 5.000000s
Traceback (most recent call last):
  File "/usr/local/lib/python3.5/site-packages/pychromecast/socket_client.py", line 233, in initialize_connection
    self.socket.connect((self.host, self.port))
  File "/usr/local/lib/python3.5/ssl.py", line 1019, in connect
    self._real_connect(addr, False)
  File "/usr/local/lib/python3.5/ssl.py", line 1006, in _real_connect
    socket.connect(self, addr)
socket.timeout: timed out
16-10-27 16:32:45 pychromecast.socket_client: Heartbeat timeout, resetting connection
16-10-27 16:33:03 pychromecast.socket_client: Failed to connect, retrying in 5.000000s
Traceback (most recent call last):
  File "/usr/local/lib/python3.5/site-packages/pychromecast/socket_client.py", line 233, in initialize_connection
    self.socket.connect((self.host, self.port))
  File "/usr/local/lib/python3.5/ssl.py", line 1019, in connect
    self._real_connect(addr, False)
  File "/usr/local/lib/python3.5/ssl.py", line 1006, in _real_connect
    socket.connect(self, addr)
OSError: [Errno 113] No route to host
16-10-27 16:35:53 pychromecast.socket_client: Heartbeat timeout, resetting connection
16-10-27 16:36:23 pychromecast.socket_client: Failed to connect, retrying in 5.000000s
Traceback (most recent call last):
  File "/usr/local/lib/python3.5/site-packages/pychromecast/socket_client.py", line 233, in initialize_connection
    self.socket.connect((self.host, self.port))
  File "/usr/local/lib/python3.5/ssl.py", line 1019, in connect
    self._real_connect(addr, False)
  File "/usr/local/lib/python3.5/ssl.py", line 1006, in _real_connect
    socket.connect(self, addr)
socket.timeout: timed out
16-10-27 16:38:16 pychromecast.socket_client: Heartbeat timeout, resetting connection
16-10-27 16:38:46 pychromecast.socket_client: Failed to connect, retrying in 5.000000s
Traceback (most recent call last):
  File "/usr/local/lib/python3.5/site-packages/pychromecast/socket_client.py", line 233, in initialize_connection
    self.socket.connect((self.host, self.port))
  File "/usr/local/lib/python3.5/ssl.py", line 1019, in connect
    self._real_connect(addr, False)
  File "/usr/local/lib/python3.5/ssl.py", line 1006, in _real_connect
    socket.connect(self, addr)
socket.timeout: timed out
16-10-27 16:39:57 netdisco.ssdp: Error fetching description at http://192.168.1.108:60878/sony/webapi/ssdp/dd.xml
16-10-27 16:39:57 pychromecast.socket_client: Error communicating with socket, resetting connection
16-10-27 16:40:12 netdisco.ssdp: Error fetching description at http://192.168.1.108:38020/dd.xml
16-10-27 16:43:51 pychromecast.socket_client: Heartbeat timeout, resetting connection
16-10-27 16:44:21 pychromecast.socket_client: Failed to connect, retrying in 5.000000s
Traceback (most recent call last):
  File "/usr/local/lib/python3.5/site-packages/pychromecast/socket_client.py", line 233, in initialize_connection
    self.socket.connect((self.host, self.port))
  File "/usr/local/lib/python3.5/ssl.py", line 1019, in connect
    self._real_connect(addr, False)
  File "/usr/local/lib/python3.5/ssl.py", line 1006, in _real_connect
    socket.connect(self, addr)
socket.timeout: timed out
16-10-27 16:44:57 pychromecast.socket_client: Heartbeat timeout, resetting connection
16-10-27 16:45:27 pychromecast.socket_client: Failed to connect, retrying in 5.000000s
Traceback (most recent call last):
  File "/usr/local/lib/python3.5/site-packages/pychromecast/socket_client.py", line 233, in initialize_connection
    self.socket.connect((self.host, self.port))
  File "/usr/local/lib/python3.5/ssl.py", line 1019, in connect
    self._real_connect(addr, False)
  File "/usr/local/lib/python3.5/ssl.py", line 1006, in _real_connect
    socket.connect(self, addr)
socket.timeout: timed out
